<mujoco model="aliengo_description">
    <compiler angle="radian" meshdir="../meshes" />
    <size njmax="500" nconmax="100" nuser_actuator="1" />

    <option timestep="0.001" iterations="50" tolerance="1e-10" solver="Newton" jacobian="dense" cone="elliptic" impratio="100" />

    <default>
        <joint damping="2" armature="0.01" frictionloss="0.2" />
        <motor ctrllimited="false" forcelimited="false"/>
		

		<default class="collision">
			<geom condim="3" friction="0.6 0.3 0.3" rgba="0.5 0.6 0.7 1" group="3" />
		</default>
		<default class="visual">
			<geom condim="3" type="mesh" group="1" conaffinity="0" contype="0" rgba="0.2 0.2 0.2 1" />
		</default>
    </default>

    <visual>
        <map force="0.01" zfar="30"/>
        <rgba haze="0.15 0.25 0.35 1"/>
        <quality shadowsize="2048"/>
        <global offwidth="800" offheight="800"/>
    </visual>

    <asset>
        <mesh name="trunk_mesh" file="trunk.stl" />
        <mesh name="hip_mesh" file="hip.stl" />
        <mesh name="thigh_mirror_mesh" file="thigh_mirror.stl" />
	<mesh name="calf_mesh" file="calf.stl" />
        <mesh name="thigh_mesh" file="thigh.stl" />
	
        <texture type="skybox" builtin="gradient" rgb1="0.3 0.5 0.7" rgb2="0 0 0" width="512" height="512"/> 
    </asset>

    <worldbody>
        <light mode="targetbodycom" target="trunk" directional="false" diffuse=".8 .8 .8" specular="0.3 0.3 0.3" pos="0 0 4.0" dir="0 0 -1"/>       

	<!-- trunk -->
        <body name="trunk" pos="0 0 0.55">
            <inertial pos="0.00846406 0.00404455 -0.000762916" quat="-3.12625e-05 0.708321 0.00247254 0.705886" mass="9.042" diaginertia="0.174706 0.161175 0.033357" />
            <freejoint name="root"/>
            <geom class="collision" size="0.3235 0.075 0.056" type="box" />
	    <geom class="visual" mesh="trunk_mesh" />
	    <!-- site for root imu sensor -->
            <site name="imu" size="0.0005 0.0005 0.0005" pos="0 0 0" />
	    <!-- front right -->
	    <body name="FR_hip" pos="0.2399 -0.051 0">
		<inertial pos="-0.022191 -0.015144 -1.5e-05" quat="0.0135493 0.706835 -0.0117635 0.707151" mass="1.993" diaginertia="0.00558695 0.00491009 0.00290132" />
		<joint name="FR_hip_joint" axis="1 0 0" limited="true" range="-1.22173 1.22173" />
		<geom class="collision" size="0.046 0.0209" pos="0 -0.083 0" quat="0.707107 0.707107 0 0" type="cylinder" />
		<geom class="visual"  quat="0 1 0 0" mesh="hip_mesh" />
		<body name="FR_thigh" pos="0 -0.083 0">
		    <inertial pos="-0.005607 0.003877 -0.048199" quat="0.694544 -0.0335669 -0.031246 0.717987" mass="0.639" diaginertia="0.0058474 0.00571186 0.000324584" />
		    <joint name="FR_thigh_joint" axis="0 1 0" limited="false" />
		    <geom class="collision" size="0.125 0.0187 0.0215" pos="0 0 -0.125" quat="0.707107 0 0.707107 0" type="box" />
		    <geom class="visual" mesh="thigh_mirror_mesh" />
		    <body name="FR_calf" pos="0 0 -0.25">
			<inertial pos="0.00215606 4.88427e-05 -0.166671" quat="0.707462 0.00517582 0.00535172 0.706712" mass="0.267" diaginertia="0.00690975 0.00689712 5.4885e-05" />
			<joint name="FR_calf_joint" axis="0 1 0" limited="true" range="-2.77507 -0.645772" />
			<geom class="collision" size="0.125 0.0104 0.008" pos="0 0 -0.125" quat="0.707107 0 0.707107 0" type="box" />
			<geom class="visual" mesh="calf_mesh" />
			<body name="FR_foot" pos="0 0 -0.25">
			    <geom class="collision" size="0.0265" pos="0 0 0" rgba="0 0.8 0 1" type="sphere" />
			</body>
		    </body>
		</body>
	    </body>
	    <!-- front left -->
	    <body name="FL_hip" pos="0.2399 0.051 0">
		<inertial pos="-0.022191 0.015144 -1.5e-05" quat="-0.0135493 0.706835 0.0117635 0.707151" mass="1.993" diaginertia="0.00558695 0.00491009 0.00290132" />
		<joint name="FL_hip_joint" axis="1 0 0" limited="true" range="-1.22173 1.22173" />
		<geom class="collision" size="0.046 0.0209" pos="0 0.083 0" quat="0.707107 0.707107 0 0" type="cylinder" />
		<geom class="visual" quat="1 0 0 0" mesh="hip_mesh" />
		<body name="FL_thigh" pos="0 0.083 0">
		    <inertial pos="-0.005607 -0.003877 -0.048199" quat="0.717987 -0.031246 -0.0335669 0.694544" mass="0.639" diaginertia="0.0058474 0.00571186 0.000324584" />
		    <joint name="FL_thigh_joint" axis="0 1 0" limited="false" />
		    <geom class="collision" size="0.125 0.0187 0.0215" pos="0 0 -0.125" quat="0.707107 0 0.707107 0" type="box" />
		    <geom class="visual" mesh="thigh_mesh" />
		    <body name="FL_calf" pos="0 0 -0.25">
			<inertial pos="0.00215606 4.88427e-05 -0.166671" quat="0.707462 0.00517582 0.00535172 0.706712" mass="0.267" diaginertia="0.00690975 0.00689712 5.4885e-05" />
			<joint name="FL_calf_joint" axis="0 1 0" limited="true" range="-2.77507 -0.645772" />
			<geom class="collision" size="0.125 0.0104 0.008" pos="0 0 -0.125" quat="0.707107 0 0.707107 0" type="box" />
			<geom class="visual" mesh="calf_mesh" />
			<body name="FL_foot" pos="0 0 -0.25">
			    <geom class="collision" size="0.0265" pos="0 0 0" rgba="0 0.8 0 1" type="sphere" />
			</body>
		    </body>
		</body>
	    </body>
	    <!-- rear right -->
	    <body name="RR_hip" pos="-0.2399 -0.051 0">
		<inertial pos="0.022191 -0.015144 -1.5e-05" quat="-0.0117635 0.707151 0.0135493 0.706835" mass="1.993" diaginertia="0.00558695 0.00491009 0.00290132" />
		<joint name="RR_hip_joint" axis="1 0 0" limited="true" range="-1.22173 1.22173" />
		<geom class="collision" size="0.046 0.0209" pos="0 -0.083 0" quat="0.707107 0.707107 0 0" type="cylinder" />
		<geom class="visual" quat="0 0 0 -1" mesh="hip_mesh" />
		<body name="RR_thigh" pos="0 -0.083 0">
		    <inertial pos="-0.005607 0.003877 -0.048199" quat="0.694544 -0.0335669 -0.031246 0.717987" mass="0.639" diaginertia="0.0058474 0.00571186 0.000324584" />
		    <joint name="RR_thigh_joint" axis="0 1 0" limited="false" />
		    <geom class="collision" size="0.125 0.0187 0.0215" pos="0 0 -0.125" quat="0.707107 0 0.707107 0" type="box" />
		    <geom class="visual" mesh="thigh_mirror_mesh" />
		    <body name="RR_calf" pos="0 0 -0.25">
			<inertial pos="0.00215606 4.88427e-05 -0.166671" quat="0.707462 0.00517582 0.00535172 0.706712" mass="0.267" diaginertia="0.00690975 0.00689712 5.4885e-05" />
			<joint name="RR_calf_joint" axis="0 1 0" limited="true" range="-2.77507 -0.645772" />
			<geom class="collision" size="0.125 0.0104 0.008" pos="0 0 -0.125" quat="0.707107 0 0.707107 0" type="box" />
			<geom class="visual" mesh="calf_mesh" />
			<body name="RR_foot" pos="0 0 -0.25">
			    <geom class="collision" size="0.0265" pos="0 0 0" rgba="0 0.8 0 1" type="sphere" />
			</body>
		    </body>
		</body>
	    </body>
	    <!-- rear left -->
	    <body name="RL_hip" pos="-0.2399 0.051 0">
		<inertial pos="0.022191 0.015144 -1.5e-05" quat="0.0117635 0.707151 -0.0135493 0.706835" mass="1.993" diaginertia="0.00558695 0.00491009 0.00290132" />
		<joint name="RL_hip_joint" axis="1 0 0" limited="true" range="-1.22173 1.22173" />
		<geom class="collision" size="0.046 0.0209" pos="0 0.083 0" quat="0.707107 0.707107 0 0" type="cylinder" />
		<geom class="visual" quat="0 0 1 0" mesh="hip_mesh" />
		<body name="RL_thigh" pos="0 0.083 0">
		    <inertial pos="-0.005607 -0.003877 -0.048199" quat="0.717987 -0.031246 -0.0335669 0.694544" mass="0.639" diaginertia="0.0058474 0.00571186 0.000324584" />
		    <joint name="RL_thigh_joint" axis="0 1 0" limited="false" />
		    <geom class="collision" size="0.125 0.0187 0.0215" pos="0 0 -0.125" quat="0.707107 0 0.707107 0" type="box" />
		    <geom class="visual" mesh="thigh_mesh" />
		    <body name="RL_calf" pos="0 0 -0.25">
			<inertial pos="0.00215606 4.88427e-05 -0.166671" quat="0.707462 0.00517582 0.00535172 0.706712" mass="0.267" diaginertia="0.00690975 0.00689712 5.4885e-05" />
			<joint name="RL_calf_joint" axis="0 1 0" limited="true" range="-2.77507 -0.645772" />
			<geom class="collision" size="0.125 0.0104 0.008" pos="0 0 -0.125" quat="0.707107 0 0.707107 0" type="box" />
			<geom class="visual" mesh="calf_mesh" />
			<body name="RL_foot" pos="0 0 -0.25">
			    <geom class="collision" size="0.0265" pos="0 0 0" rgba="0 0.8 0 1" type="sphere" />
			</body>
		    </body>
		</body>
	    </body>
	</body>
    </worldbody>

    <actuator>
        <!-- FR leg -->
        <motor name="FR_hip_motor" joint="FR_hip_joint" />
        <motor name="FR_thigh_motor" joint="FR_thigh_joint" />
        <motor name="FR_calf_motor" joint="FR_calf_joint" />
        <!-- FL leg -->
        <motor name="FL_hip_motor" joint="FL_hip_joint" />
        <motor name="FL_thigh_motor" joint="FL_thigh_joint" />
        <motor name="FL_calf_motor" joint="FL_calf_joint" />
        <!-- RR leg -->
        <motor name="RR_hip_motor" joint="RR_hip_joint" />
        <motor name="RR_thigh_motor" joint="RR_thigh_joint" />
        <motor name="RR_calf_motor" joint="RR_calf_joint" />
        <!-- RL leg -->
        <motor name="RL_hip_motor" joint="RL_hip_joint" />
        <motor name="RL_thigh_motor" joint="RL_thigh_joint" />
        <motor name="RL_calf_motor" joint="RL_calf_joint" />
    </actuator>

    <sensor>
	<!-- imu -->
	<gyro          name="Accelerometer_gyro"     site="imu" />
	<accelerometer name="Accelerometer_accelerometer"    site="imu" />
    </sensor>

</mujoco>
